<?xml version="1.0" ?>
<robot xmlns:xacro="http://www.ros.org/wiki/xacro" 
 name="sia_manipulator">

  
  
  <material name ="Blue">
    <color rgba="0.137 0.49412 0.74902 1"/>
  </material>
  <material name ="Black">
    <color rgba="0 0 0 0.8"/>
  </material>
  <material name ="Dark Blue">
    <color rgba="0.098 0.098 0.439 1.0"/>
  </material>
  <material name ="light Blue">
    <color rgba="0.387 0.584 0.93 1.0"/>
  </material>
  <material name ="White">
    <color rgba="1 1 1 1"/>
  </material>
  <material name ="Antique White">
    <color rgba="0.98 0.92 0.84 1"/>
  </material>
  <material name ="Dark Gray">
    <color rgba="0.537 0.594 0.74902 1"/>
  </material>
  <material name ="Gray">
    <color rgba="0.537 0.594 0.74 1"/>
  </material>
  <material name ="Silver">
      <color rgba="0.588 0.588 0.588 1"/>
  </material>
  <material name ="Red">
      <color rgba="1.00 0 0 1.0"/>
    <xacro:property name="PI" value="3.1415926" />
  </material>
  <!-- base_link -->
  <!-- 存在问题，质量惯性矩阵？ -->
    <link name="base_link">
      <visual>
        <origin rpy="0 0 0" xyz="0 0 0"/>
        <geometry>
          <mesh filename="package://sia_manipulator_description/meshes/base.dae"/>
        </geometry>
        <material name ="Gray"/>
      </visual>
    <collision>
        <origin rpy="0 0 0" xyz="0 0 0"/>
        <geometry>
          <mesh filename="package://sia_manipulator_description/meshes/base.stl"/>
        </geometry>
      </collision>
      <!-- 复制 -->
      <inertial>
        <mass value="12.369"/>
        <inertia ixx="0.069552066" ixy="0.000045456" ixz="0.000067368" iyy="0.0682463" iyz="0.000262322" izz="0.054371276"/>
      </inertial>
    </link>

  <!-- shoulder -->
  <link name="shoulder">
       <visual>
      <origin rpy="0 0 0" xyz="0 0 0"/>
      <geometry>
        <mesh filename="package://sia_manipulator_description/meshes/link1.dae"/>
      </geometry>
      <material name ="Blue"/>
    </visual>
    <collision>
      <origin rpy="0 0 0" xyz="0 0 0"/>
      <geometry>
        <mesh filename="package://sia_manipulator_description/meshes/link1.stl"/>
      </geometry>
    </collision>
    <inertial>
      <mass value="12.369"/>
      <inertia ixx="0.069552066" ixy="0.000045456" ixz="0.000067368" iyy="0.0682463" iyz="0.000262322" izz="0.054371276"/>
    </inertial>
    </link>
  <!-- shoulder_joint -->
  <joint name="shoulder_joint" type="revolute">
      <origin rpy="0 0 ${-pi/2}" xyz="0 0 0.165"/>
      <parent link="base_link"/>
      <child link="shoulder"/>
      <axis xyz="0 0 1"/>
      <limit effort="140" lower="${-pi}" upper="${pi}" velocity="${65*pi/180}"/>
      <dynamics damping="0.0" friction="0.0"/>
      
    </joint>
  <!-- upper_arm -->
  <link name="upper_arm">
      <visual>
        <origin rpy="0 0 0" xyz="0 0 0"/>
        <geometry>
          <mesh filename="package://sia_manipulator_description/meshes/link2.dae"/>
        </geometry>
        <material name ="Gray"/>
      </visual>
      <collision>
        <origin rpy="0 0 0" xyz="0 0 0"/>
        <geometry>
          <mesh filename="package://sia_manipulator_description/meshes/link2.stl"/>
        </geometry>
      </collision>
      <inertial>
        <mass value="23.055"/>
        <inertia ixx="0.097114219" ixy="0.000031977" ixz="0.096025722" iyy="3.624394224" iyz="-0.000010802" izz="3.614501336"/>
      </inertial>
    </link>
  <!-- upper_arm_joint -->
  <joint name="upper_arm_joint" type="revolute">
      <origin rpy="${-pi/2} ${-pi/2} 0" xyz="0 0.164 0"/>
      <parent link="shoulder"/>
      <child link="upper_arm"/>
      <axis xyz="0 0 1"/>
      <limit effort="140" lower="${-pi}" upper="${pi}" velocity="${65*pi/180}"/>
      <dynamics damping="0.0" friction="0.0"/>
    </joint>

  <!-- forearm -->
  <link name="forearm">
      <visual>
        <origin rpy="0 0 0" xyz="0 0 0"/>
        <geometry>
          <mesh filename="package://sia_manipulator_description/meshes/link3.dae"/>
        </geometry>
      <material name ="Blue"/>
      </visual>
      <collision>
        <origin rpy="0 0 0" xyz="0 0 0"/>
        <geometry>
          <mesh filename="package://sia_manipulator_description/meshes/link3.stl"/>
        </geometry>
      </collision>
      <inertial>
        <origin rpy="0 0 0" xyz="0.000000 0.000000 0.000000"/>
        <mass value="6.808"/>
        <inertia ixx="0.112801117" ixy="-0.112801117" ixz="-0.317954508" iyy="1.672231427" iyz="0.000205154" izz="1.575646813"/>
      </inertial>
    </link>
  <!-- forearm_joint -->
  <joint name="forearm_joint" type="revolute">
      <origin rpy="0 0 0" xyz="0.608 0 0"/>
      <parent link="upper_arm"/>
      <child link="forearm"/>
      <axis xyz="0 0 1"/>
      <limit effort="140.0" lower="${-160/180*pi}" upper="${160/180*pi}" velocity="${105*pi/180}"/>
      <dynamics damping="0.0" friction="0.0"/>
    </joint>
  <!-- wrist_1 -->
  <link name="wrist_1">
      <visual>
        <origin rpy="0 0 0" xyz="0 0 0"/>
        <geometry>
          <mesh filename="package://sia_manipulator_description/meshes/link4.dae"/>
        </geometry>
        <material name ="Gray"/>
      </visual>
      <collision>
        <origin rpy="0 0 0" xyz="0 0 0"/>
        <geometry>
          <mesh filename="package://sia_manipulator_description/meshes/link4.stl"/>
        
        </geometry>
      </collision>
      <inertial>
        <origin rpy="0 0 0" xyz="0.000000 0.000000 0.000000"/>
        <mass value="3.579"/>
        <inertia ixx="0.010470895" ixy="0.000061784" ixz="0.00000228" iyy="0.006243529" iyz="-0.000040702" izz="0.010424802"/>
      </inertial>
    </link>
  <!-- wrist_1_joint -->
  <joint name="wrist_1_joint" type="revolute">
      <origin rpy="0 0 ${pi/2}" xyz="0.566 0 0"/>
      <parent link="forearm"/>
      <child link="wrist_1"/>
      <axis xyz="0 0 1"/>
      <limit effort="140" lower="${-pi}" upper="${pi}" velocity="${165*pi/180}"/>
      <dynamics damping="0.0" friction="0.0"/>
    </joint>
  <!-- wrist_2 -->
  <link name="wrist_2">
      <visual>
        <origin rpy="0 0 0" xyz="0 0 0"/>
        <geometry>
          <mesh filename="package://sia_manipulator_description/meshes/link5.dae"/>
        </geometry>
      <material name ="Blue"/>
      </visual>
      <collision>
        <origin rpy="0 0 0" xyz="0 0 0"/>
        <geometry>
          <mesh filename="package://sia_manipulator_description/meshes/link5.stl"/>
        </geometry>
      </collision>
      <inertial>
        <origin rpy="0 0 0" xyz="0.000000 0.000000 0.000000"/>
        <mass value="3.579"/>
        <inertia ixx="0.010470895" ixy="0.000061784" ixz="-0.00000228" iyy="0.006243529" iyz="0.000040702" izz="0.010424802"/>
      </inertial>
    </link>
  <!-- wrist_2_joint -->
  <joint name="wrist_2_joint" type="revolute">
      <origin rpy="${pi/2} 0 0" xyz="0 -0.126 0"/>
      <parent link="wrist_1"/>
      <child link="wrist_2"/>
      <axis xyz="0 0 1"/>
      
      <limit effort="140.0" lower="${-pi}" upper="${pi}" velocity="${165*pi/180}"/>
      <dynamics damping="0.0" friction="0.0"/>
    </joint>
  <!-- wrist_3 -->
  <link name="wrist_3">
      <visual>
        <origin rpy="0 0 0" xyz="0 0 0"/>
        <geometry>
          <mesh filename="package://sia_manipulator_description/meshes/link6.dae"/>
        </geometry>
        <material name ="Red"/>
      </visual>
      <collision>
        <origin rpy="0 0 0" xyz="0 0 0"/>
        <geometry>
          <mesh filename="package://sia_manipulator_description/meshes/link6.stl"/>
        </geometry>
      </collision>
      <inertial>
        <origin rpy="0 0 0" xyz="0.000000 0.000000 0.000000"/>
        <mass value="0.477"/>
        <inertia ixx="0.000742141" ixy="0.000000009" ixz="-0.000010713" iyy="0.000761498" iyz="0.000004274" izz="0.001029656"/>
      </inertial>
    </link>
  <!-- wrist_3_joint -->
  <joint name="wrist_3_joint" type="revolute">
      <origin rpy="${-pi/2} 0 0" xyz="0 0.113 0"/>
      <parent link="wrist_2"/>
      <child link="wrist_3"/>
      <axis xyz="0 0 1"/>
      <limit effort="140.0" lower="${-pi}" upper="${pi}" velocity="${165*pi/180}"/>
    </joint> 
  
  
</robot>
