<?xml version="1.0" encoding="utf-8"?>
<!-- This URDF was automatically created by SolidWorks to URDF Exporter! Originally created by Stephen Brawner (brawner@gmail.com) 
     Commit Version: 1.6.0-1-g15f4949  Build Version: 1.6.7594.29634
     For more information, please see http://wiki.ros.org/sw_urdf_exporter -->

<robot xmlns:xacro="http://www.ros.org/wiki/xacro" 
  name="sia_agv3">
  <xacro:property name="universial_wheel_radius" value="0.0325" />
  <xacro:property name="PI" value="3.1415926" />
  <xacro:property name="drive_wheel_radius" value="0.075" />
  <xacro:property name="drive_wheel_thickness" value="0.045" />
<!-- 支架_front -->
  <xacro:macro name="bracket_func_front" params="bracket_name_front flag" >
    <link name="${bracket_name_front}">
      <inertial>
        <origin xyz="-0.000336543565982339 0.0067145336674802 -0.0138488838342261" rpy="0 0 0" />
        <mass value="0.0728108307863773" />
        <inertia ixx="2.279226907759E-05" ixy="-1.52431962880911E-07" ixz="-1.17033639983441E-07"
                                          iyy="2.43402166733781E-05"  iyz="1.19958125852891E-06"
                                                                      izz="3.97943793169979E-05" />
      </inertial>
      <visual>
        <origin xyz="0 0 0" rpy="0 0 0" />
        <geometry>
          <mesh filename="package://sia_agv3/meshes/agv_axis1.dae" />
        </geometry>
      </visual>
    </link>

     <joint name="${bracket_name_front}_joint" type="continuous">
        <origin xyz="${flag*0.194} 0.59537 -0.604" rpy="0 0 0" />
        <parent link="base_link"  />
        <child link="${bracket_name_front}" />
        <axis   xyz="0 0 -1" />
        <limit  lower="-${PI}" upper="${PI}" effort="0" velocity="0" />
      </joint>
  </xacro:macro>
<!-- 支架_rear -->
  <xacro:macro name="bracket_func_rear" params="bracket_name flag" >
    <link name="${bracket_name}">
    <inertial>
      <origin
        xyz="0.000273986900293122 0.00609743706279098 -0.0161440693104884" rpy="0 0 0" />
      <mass
        value="0.0728108291695974" />
      <inertia
        ixx="2.27797981840266E-05"
        ixy="-6.14434156285646E-08"
        ixz="-4.70056384567012E-08"
        iyy="2.43526875822419E-05"
        iyz="1.20436001342095E-06"
        izz="3.97943792246835E-05" />
    </inertial>
    <visual>
      <origin
        xyz="0 0 0" rpy="0 0 0" />
      <geometry>
        <mesh
          filename="package://sia_agv3/meshes/agv_axis1.dae" />
      </geometry>
    </visual>
    </link>
    <joint name="${bracket_name}_joint" type="continuous">
        <origin  xyz="${flag*0.18} -0.0885 -0.604" rpy="0 0 0" />
        <parent link="base_link"  />
        <child link="${bracket_name}" />
        <axis   xyz="0 0 -1" />
        <limit  lower="-${PI}" upper="${PI}" effort="0" velocity="0" />
    </joint>
  </xacro:macro>
    
<!-- 大轮 -->
  <xacro:macro name="drive_wheel_func" params="wheel_name flag" >
    <link name="${wheel_name}">
      <inertial>
        <origin
          xyz="-6.93889390390723E-18 0 0.00168998379535312" rpy="0 0 0" />
        <mass
          value="0.418358558488212" />
        <inertia
          ixx="0.000915617766712358"
          ixy="3.32582077666032E-20"
          ixz="1.88985288748301E-20"
          iyy="0.000915617766712358"
          iyz="-8.76135733408917E-21"
          izz="0.00170660288564837" />
      </inertial>
      <visual>
        <origin
          xyz="0 0 0" rpy="0 0 0" />
        <geometry>
          <mesh
            filename="package://sia_agv3/meshes/agv_drive_wheel.dae" />
        </geometry>
        <material
          name="">
          <color rgba="1 1 0.501960784313725 1" />
        </material>
      </visual>
      <collision>
        <origin
          xyz="0 0 0" rpy="0 0 0" />
        <geometry>
          <cylinder radius="${drive_wheel_radius}" length="${drive_wheel_thickness}" />
        </geometry>
      </collision>
    </link>
    <joint name="${wheel_name}_joint" type="continuous">
        <origin
          xyz="${flag*0.2595} 0.2765 -0.604" rpy="1.5708 0 -1.5708" />
        <parent link="base_link" />
        <child link="${wheel_name}" />
        <axis xyz="0 0 1" />
        <limit lower="-${PI}" upper="${PI}" effort="0" velocity="0" />
    </joint>
  </xacro:macro>
<!-- 万象轮 -->
  <xacro:macro name="universial_wheel_func" params="wheel_name flag" >
    <link name="${wheel_name}_wheel">
      <inertial>
        <origin xyz="8.63289463803874E-08 -6.61745890639942E-07 2.14074135862496E-07" rpy="0 0 0" />
        <mass value="0.126066298764299" />
        <inertia ixx="3.69211742911089E-05" ixy="3.29619978086518E-12" ixz="1.35062822981863E-10"
                                            iyy="3.6921114726363E-05"  iyz="-1.54062454753047E-09"
                                                                      izz="6.47847019668671E-05" />
      </inertial>
      <visual>
        <origin xyz="0 0 0" rpy="0 0 0" />
        <geometry>
          <mesh filename="package://sia_agv3/meshes/agv_universal_wheel.dae" />
        </geometry>
      </visual>
      <collision>
        <origin xyz="0 0 0" rpy="0 0 0" />
      
        <geometry>
            <sphere radius="${universial_wheel_radius}"/>
          </geometry> 
       
      </collision>
    </link>
    <joint name="${wheel_name}_wheel_joint" type="continuous">
      <origin xyz="0.0 0.0199 -0.0425" rpy="1.57 0.0 -1.57" />
      <parent
        link="${wheel_name}" />
      <child
        link="${wheel_name}_wheel" />
      <axis
        xyz="0 0 -1" />
      <limit
        lower="-${PI}" upper="${PI}" effort="0" velocity="0" />
    </joint>
  </xacro:macro>
<!-- 雷达 -->
   <xacro:macro name="laser_func" params="laser_name flag" >
      <link name="${laser_name}_link">
      <inertial>
        <origin
          xyz="6.33688978618485E-06 -5.59744645495797E-05 0.0278383378698622" rpy="0 0 0" />
        <mass value="0.216211395934109" />
        <inertia
          ixx="0.000130773887841249"
          ixy="2.26503861750725E-08"
          ixz="-3.28530461658848E-08"
          iyy="0.000130567645197807"
          iyz="2.90267159366494E-07"
          izz="0.000128913789383877" />
      </inertial>
      <visual>
        <origin
          xyz="0 0 0" rpy="0 0 0" />
        <geometry>
          <mesh
            filename="package://sia_agv3/meshes/agv_laser_link.dae" />
        </geometry>
        <material
          name="">
          <color
            rgba="1 1 0.501960784313725 1" />
        </material>
      </visual>
    </link>
    <joint
      name="${laser_name}_joint" type="fixed">
      <origin
        xyz="0 0.67006 -0.529" rpy="0 0 0" />
      <parent
        link="base_link" />
      <child
        link="${laser_name}_link" />
      <axis
        xyz="0 0 -1" />
      <limit
        lower="-${PI}" upper="${PI}" effort="0" velocity="0" />
    </joint>
</xacro:macro>

  <link  name="base_link">
    <inertial>
      <origin
        xyz="-0.000543863853506091 0.282716810863512 -0.36138635137112"
        rpy="0 0 0" />
      <mass
        value="29.2907917401275" />
      <inertia
        ixx="0.658416147229005"
        ixy="0.000444325594903029"
        ixz="-5.22965035739952E-05"
        iyy="0.481294666894637"
        iyz="0.000150147215019541"
        izz="0.989603236439599" />
    </inertial>
    <visual>
      <origin
        xyz="0 0 0"
        rpy="0 0 0" />
      <geometry>
        <mesh
          filename="package://sia_agv3/meshes/agv_base_link.dae" />
      </geometry>
      <material
        name="">
        <color
          rgba="1 1 1 1" />
      </material>
      <kinematic>1</kinematic>
    </visual>
    <collision>
      <origin
        xyz="0 0 0"
        rpy="0 0 0" />
      <geometry>
        <box size="0.925 0.585 0.67" />
      </geometry>
    </collision>
  </link>
  <xacro:bracket_func_front bracket_name_front="right_front" flag="1" />
  <xacro:bracket_func_front bracket_name_front="left_front" flag="-1" />
  <xacro:bracket_func_rear bracket_name="right_rear" flag="1" />
  <xacro:bracket_func_rear bracket_name="left_rear" flag="-1" />
  <xacro:drive_wheel_func wheel_name="right_wheel" flag="1" />
  <xacro:drive_wheel_func wheel_name="left_wheel" flag="-1" />
  <xacro:universial_wheel_func wheel_name="left_front" flag="-1" />
  <xacro:universial_wheel_func wheel_name="right_front" flag="-1" />
  <xacro:universial_wheel_func wheel_name="right_rear" flag="-1" />
  <xacro:universial_wheel_func wheel_name="left_rear" flag="-1" />
  <xacro:laser_func laser_name="laser" flag="-1" />
</robot>