<?xml version="1.0" encoding="utf-8"?>
<!-- This URDF was automatically created by SolidWorks to URDF Exporter! Originally created by Stephen Brawner (brawner@gmail.com) 
     Commit Version: 1.6.0-1-g15f4949  Build Version: 1.6.7594.29634
     For more information, please see http://wiki.ros.org/sw_urdf_exporter -->

<robot xmlns:xacro="http://www.ros.org/wiki/xacro" 
  name="sia_agv3">
  <link
    name="base_link">
    <inertial>
      <origin
        xyz="-0.000543863853506091 0.282716810863512 -0.36138635137112"
        rpy="0 0 0" />
        
        <!-- <origin
        xyz="-0.000543863853506091 0.282716810863512 1.36138635137112"
        rpy="0 0 0" /> -->
      <mass
        value="29.2907917401275" />
      <inertia
        ixx="0.658416147229005"
        ixy="0.000444325594903029"
        ixz="-5.22965035739952E-05"
        iyy="0.481294666894637"
        iyz="0.000150147215019541"
        izz="0.989603236439599" />
    </inertial>
    <visual>
      <origin
        xyz="0 0 0"
        rpy="0 0 0" />
      <geometry>
        <mesh
          filename="package://sia_agv3/meshes/agv_base_link.dae" />
      </geometry>
      <material
        name="">
        <color
          rgba="1 1 1 1" />
      </material>
      <kinematic>1</kinematic>
    </visual>
    <collision>
      <origin
        xyz="0 0 0"
        rpy="0 0 0" />
      <geometry>
        <box size="0.5 0.5 0.5" />
      </geometry>
    </collision>
  </link>
  <link
    name="left_front">
    <inertial>
      <origin
        xyz="-0.000336543565982339 0.0067145336674802 -0.0138488838342261"
        rpy="0 0 0" />
      <mass
        value="0.0728108307863773" />
      <inertia
        ixx="2.279226907759E-05"
        ixy="-1.52431962880911E-07"
        ixz="-1.17033639983441E-07"
        iyy="2.43402166733781E-05"
        iyz="1.19958125852891E-06"
        izz="3.97943793169979E-05" />
    </inertial>
    <visual>
      <origin
        xyz="0 0 0"
        rpy="0 0 0" />
      <geometry>
        <mesh
          filename="package://sia_agv3/meshes/agv_axis2.dae" />
      </geometry>
      <material
        name="">
        <color
          rgba="1 1 0.501960784313725 1" />
      </material>
    </visual>
    <collision>
      <origin
        xyz="0 0 0"
        rpy="0 0 0" />
     <geometry>
        <!-- <box size="0.5 0.5 0.5" /> -->
        <cylinder radius="0.0325" length="0.016" />
      </geometry>
    </collision>
  </link>
  <joint
    name="left_front_joint"
    type="continuous">
    <origin
      xyz="-0.194 0.59539 -0.604"
      rpy="0 0 0" />
    <parent
      link="base_link" />
    <child
      link="left_front" />
    <axis
      xyz="0 0 -1" />
    <limit
      lower="-3.14"
      upper="3.14"
      effort="0"
      velocity="0" />
  </joint>
  <link
    name="left_front_wheel">
    <inertial>
      <origin
        xyz="1.54128708518275E-07 -6.35365208223604E-07 -2.08668753956531E-07"
        rpy="0 0 0" />
      <mass
        value="0.126066263473178" />
      <inertia
        ixx="3.69211700768695E-05"
        ixy="1.59275080958781E-11"
        ixz="-4.07947748521245E-10"
        iyy="3.69211197129469E-05"
        iyz="1.49202086216788E-09"
        izz="6.47847031089787E-05" />
    </inertial>
    <visual>
      <origin
        xyz="0 0 0"
        rpy="0 0 0" />
      <geometry>
        <mesh
          filename="package://sia_agv3/meshes/agv_universal_wheel.dae" />
      </geometry>
      <material
        name="">
        <color
          rgba="1 1 0.501960784313725 1" />
      </material>
    </visual>
    <collision>
      <origin
        xyz="0 0 0"
        rpy="0 0 0" />
      <geometry>
         <cylinder radius="0.0325" length="0.05136" />
      </geometry>
    </collision>
  </link>
  <joint
    name="left_front_wheel_joint"
    type="continuous">
    <origin
      xyz="-0.0028411 0.022783 -0.0425"
      rpy="1.5708 0 -1.5708" />
    <parent
      link="left_front" />
    <child
      link="left_front_wheel" />
    <axis
      xyz="0 0 -1" />
    <limit
      lower="-3.14"
      upper="3.14"
      effort="0"
      velocity="0" />
  </joint>
  <link
    name="right_front">
    <inertial>
      <origin
        xyz="-0.000336543565982339 0.0067145336674802 -0.0138488838342261"
        rpy="0 0 0" />
      <mass
        value="0.0773960442571589" />
      <inertia
        ixx="2.79271956658027E-05"
        ixy="-2.09328673275462E-07"
        ixz="-1.86296961191266E-07"
        iyy="2.93597569308493E-05"
        iyz="-2.80412358155225E-08"
        izz="4.69036460817845E-05" />
    </inertial>
    <visual>
      <origin
        xyz="0 0 0"
        rpy="0 0 0" />
      <geometry>
        <mesh
          filename="package://sia_agv3/meshes/agv_axis2.dae" />
      </geometry>
      <material
        name="">
        <color
          rgba="0.854901960784314 0.854901960784314 0.854901960784314 1" />
      </material>
    </visual>
    <collision>
      <origin
        xyz="0 0 0"
        rpy="0 0 0" />
      <!-- <geometry>
        <mesh
          filename="package://sia_agv3/meshes/agv_axis2.dae" />
      </geometry> -->
      <geometry>
        <!-- <box size="0.5 0.5 0.5" /> -->
        <cylinder radius="0.0325" length="0.016" />
      </geometry>
    </collision>
  </link>
  <joint
    name="right_front_joint"
    type="continuous">
    <origin
      xyz="0.194 0.59535 -0.6046"
      rpy="0 0 0" />
    <parent
      link="base_link" />
    <child
      link="right_front" />
    <axis
      xyz="0 0 -1" />
    <limit
      lower="-3.14"
      upper="3.14"
      effort="0"
      velocity="0" />
  </joint>
  <link
    name="right_front_wheel">
    <inertial>
      <origin
        xyz="8.63289463803874E-08 -6.61745890639942E-07 2.14074135862496E-07"
        rpy="0 0 0" />
      <mass
        value="0.126066298764299" />
      <inertia
        ixx="3.69211742911089E-05"
        ixy="3.29619978086518E-12"
        ixz="1.35062822981863E-10"
        iyy="3.6921114726363E-05"
        iyz="-1.54062454753047E-09"
        izz="6.47847019668671E-05" />
    </inertial>
    <visual>
      <origin
        xyz="0 0 0"
        rpy="0 0 0" />
      <geometry>
        <mesh
          filename="package://sia_agv3/meshes/agv_universal_wheel.dae" />
      </geometry>
      <material
        name="">
        <color
          rgba="1 1 0.501960784313725 1" />
      </material>
    </visual>
    <collision>
      <origin
        xyz="0 0 0"
        rpy="0 0 0" />
      <!-- <geometry>
        <mesh
          filename="package://sia_agv3/meshes/agv_universal_wheel.dae" />
      </geometry> -->
      <geometry>
         <cylinder radius="0.0325" length="0.05136" />
      </geometry>
    </collision>
  </link>
  <joint
    name="right_front_wheel_joint"
    type="continuous">
    <origin
      xyz="-0.0028411 0.022783 -0.0425"
      rpy="1.5807 0.069104 -1.5708" />
    <parent
      link="right_front" />
    <child
      link="right_front_wheel" />
    <axis
      xyz="0 0 -1" />
    <limit
      lower="-3.14"
      upper="3.14"
      effort="0"
      velocity="0" />
  </joint>
  <link
    name="left_wheel">
    <inertial>
      <origin
        xyz="-6.93889390390723E-18 0 0.00168998379535312"
        rpy="0 0 0" />
      <mass
        value="0.418358558488212" />
      <inertia
        ixx="0.000915617766712358"
        ixy="3.32582077666032E-20"
        ixz="1.88985288748301E-20"
        iyy="0.000915617766712358"
        iyz="-8.76135733408917E-21"
        izz="0.00170660288564837" />
    </inertial>
    <visual>
      <origin
        xyz="0 0 0"
        rpy="0 0 0" />
      <geometry>
        <mesh
          filename="package://sia_agv3/meshes/agv_drive_wheel.dae" />
      </geometry>
      <material
        name="">
        <color
          rgba="1 1 0.501960784313725 1" />
      </material>
    </visual>
    <collision>
      <origin
        xyz="0 0 0"
        rpy="0 0 0" />
      <!-- <geometry>
        <mesh
          filename="package://sia_agv3/meshes/agv_drive_wheel.dae" />
      </geometry> -->
      <geometry>
         <cylinder radius="0.075" length="0.045" />
      </geometry>
    </collision>
  </link>
  <joint
    name="left_wheel_joint"
    type="continuous">
    <origin
      xyz="-0.2595 0.2765 -0.604"
      rpy="1.5708 0 -1.5708" />
    <parent
      link="base_link" />
    <child
      link="left_wheel" />
    <axis
      xyz="0 0 -1" />
    <limit
      lower="-3.14"
      upper="3.14"
      effort="0"
      velocity="0" />
  </joint>
  <link
    name="right_wheel">
    <inertial>
      <origin
        xyz="-6.93889390390723E-18 0 0.00168998379535312"
        rpy="0 0 0" />
      <mass
        value="0.418358558488212" />
      <inertia
        ixx="0.000915617766712358"
        ixy="3.32582077666032E-20"
        ixz="1.88985288748301E-20"
        iyy="0.000915617766712358"
        iyz="-8.76135733408917E-21"
        izz="0.00170660288564837" />
    </inertial>
    <visual>
      <origin
        xyz="0 0 0"
        rpy="0 0 0" />
      <geometry>
        <mesh
          filename="package://sia_agv3/meshes/agv_drive_wheel.dae" />
      </geometry>
      <material
        name="">
        <color
          rgba="1 1 0.501960784313725 1" />
      </material>
    </visual>
    <collision>
      <origin
        xyz="0 0 0"
        rpy="0 0 0" />
      <!-- <geometry>
        <mesh
          filename="package://sia_agv3/meshes/agv_drive_wheel.dae" />
      </geometry> -->
      <geometry>
         <cylinder radius="0.075" length="0.045" />
      </geometry>
    </collision>
  </link>
  <joint
    name="right_wheel_joint"
    type="continuous">
    <origin
      xyz="0.2595 0.27512 -0.604"
     
      rpy="1.5708 0 1.5708" />
      <!-- change -->
    <parent
      link="base_link" />
    <child
      link="right_wheel" />
    <axis
      xyz="0 0 -1" />
    <limit
      lower="-3.14"
      upper="3.14"
      effort="0"
      velocity="0" />
  </joint>
  <link
    name="left_rear">
    <inertial>
      <origin
        xyz="0.00103770002703207 0.00601472892484933 -0.0161440697345775"
        rpy="0 0 0" />
      <mass
        value="0.0728108309256295" />
      <inertia
        ixx="2.27892988966431E-05"
        ixy="1.36495284501299E-07"
        ixz="1.04643060411549E-07"
        iyy="2.43431854614664E-05"
        iyz="1.20072630984208E-06"
        izz="3.97943785025612E-05" />
    </inertial>
    <visual>
      <origin
        xyz="0 0 0"
        rpy="0 0 0" />
      <geometry>
        <mesh
          filename="package://sia_agv3/meshes/agv_axis5.dae" />
      </geometry>
      <material
        name="">
        <color
          rgba="1 1 0.501960784313725 1" />
      </material>
    </visual>
    <collision>
      <origin
        xyz="0 0 0"
        rpy="0 0 0" />
      <!-- <geometry>
        <mesh
          filename="package://sia_agv3/meshes/agv_axis5.dae" />
      </geometry> -->
      <geometry>
        <!-- <box size="0.5 0.5 0.5" /> -->
        <cylinder radius="0.0325" length="0.016" />
      </geometry>
    </collision>
  </link>
  <joint
    name="left_rear_joint"
    type="continuous">
    <origin
      xyz="-0.18 -0.0885 -0.604"
      rpy="0 0 0" />
    <parent
      link="base_link" />
    <child
      link="left_rear" />
    <axis
      xyz="0 0 -1" />
    <limit
      lower="-3.14"
      upper="3.14"
      effort="0"
      velocity="0" />
  </joint>
  <link
    name="left_rear_wheel">
    <inertial>
      <origin
        xyz="-2.5138800996416E-07 6.19546932312254E-07 1.74490358807733E-07"
        rpy="0 0 0" />
      <mass
        value="0.126066317340043" />
      <inertia
        ixx="3.71313849029771E-05"
        ixy="-1.09124836455106E-10"
        ixz="-2.41105892440028E-06"
        iyy="3.69211204624104E-05"
        iyz="1.45526694390849E-09"
        izz="6.45744854056141E-05" />
    </inertial>
    <visual>
      <origin
        xyz="0 0 0"
        rpy="0 0 0" />
      <geometry>
        <mesh
          filename="package://sia_agv3/meshes/agv_universal_wheel.dae" />
      </geometry>
      <material
        name="">
        <color
          rgba="1 1 0.501960784313725 1" />
      </material>
    </visual>
    <collision>
      <origin
        xyz="0 0 0"
        rpy="0 0 0" />
      <!-- <geometry>
        <mesh
          filename="package://sia_agv3/meshes/agv_universal_wheel.dae" />
      </geometry> -->
      <geometry>
         <cylinder radius="0.0325" length="0.05136" />
      </geometry>
    </collision>
  </link>
  <joint
    name="left_rear_wheel_joint"
    type="continuous">
    <origin
      xyz="-0.00077959 0.019985 -0.0425"
      rpy="1.5708 0 -1.5708" />
    <parent
      link="left_rear" />
    <child
      link="left_rear_wheel" />
    <axis
      xyz="0 0 1" />
    <limit
      lower="-3.14"
      upper="3.14"
      effort="0"
      velocity="0" />
  </joint>
  <link
    name="right_rear">
    <inertial>
      <origin
        xyz="0.000273986900293122 0.00609743706279098 -0.0161440693104884"
        rpy="0 0 0" />
      <mass
        value="0.0728108291695974" />
      <inertia
        ixx="2.27797981840266E-05"
        ixy="-6.14434156285646E-08"
        ixz="-4.70056384567012E-08"
        iyy="2.43526875822419E-05"
        iyz="1.20436001342095E-06"
        izz="3.97943792246835E-05" />
    </inertial>
    <visual>
      <origin
        xyz="0 0 0"
        rpy="0 0 0" />
      <geometry>
        <mesh
          filename="package://sia_agv3/meshes/agv_axis6.dae" />
      </geometry>
      <material
        name="">
        <color
          rgba="1 1 0.501960784313725 1" />
      </material>
    </visual>
    <collision>
      <origin
        xyz="0 0 0"
        rpy="0 0 0" />
      <!-- <geometry>
        <mesh
          filename="package://sia_agv3/meshes/agv_axis6.dae" />
      </geometry> -->
      <geometry>
        <!-- <box size="0.5 0.5 0.5" /> -->
        <cylinder radius="0.0325" length="0.016" />
      </geometry>
    </collision>
  </link>
  <joint
    name="right_rear_joint"
    type="continuous">
    <origin
      xyz="0.18 -0.0885 -0.604"
      rpy="0 0 0" />
    <parent
      link="base_link" />
    <child
      link="right_rear" />
    <axis
      xyz="0 0 -1" />
    <limit
      lower="-3.14"
      upper="3.14"
      effort="0"
      velocity="0" />
  </joint>
  <link
    name="right_rear_wheel">
    <inertial>
      <origin
        xyz="-2.30745561546897E-09 -7.89610055118573E-09 -9.54958800924999E-09"
        rpy="0 0 0" />
      <mass
        value="0.126061731217855" />
      <inertia
        ixx="3.69211695299971E-05"
        ixy="1.52621131934903E-11"
        ixz="-4.08287922080125E-10"
        iyy="3.69211191221606E-05"
        iyz="1.49225017362431E-09"
        izz="6.47847033079185E-05" />
    </inertial>
    <visual>
      <origin
        xyz="0 0 0"
        rpy="0 0 0" />
      <geometry>
        <mesh
          filename="package://sia_agv3/meshes/agv_universal_wheel.dae" />
      </geometry>
      <material
        name="">
        <color
          rgba="1 1 0.501960784313725 1" />
      </material>
    </visual>
    <collision>
      <origin
        xyz="0 0 0"
        rpy="0 0 0" />
      <!-- <geometry>
        <mesh
          filename="package://sia_agv3/meshes/agv_universal_wheel.dae" />
      </geometry> -->
      <geometry>
         <cylinder radius="0.0325" length="0.05136" />
      </geometry>
    </collision>
  </link>
  <joint
    name="right_rear_wheel_joint"
    type="continuous">
    <origin
      xyz="-0.00077959 0.019985 -0.0425"
      rpy="1.5708 0 -1.5708" />
    <parent
      link="right_rear" />
    <child
      link="right_rear_wheel" />
    <axis
      xyz="0 0 1" />
    <limit
      lower="-3.14"
      upper="3.14"
      effort="0"
      velocity="0" />
  </joint>
  <link
    name="laser_Link">
    <inertial>
      <origin
        xyz="6.33688978618485E-06 -5.59744645495797E-05 0.0278383378698622"
        rpy="0 0 0" />
      <mass
        value="0.216211395934109" />
      <inertia
        ixx="0.000130773887841249"
        ixy="2.26503861750725E-08"
        ixz="-3.28530461658848E-08"
        iyy="0.000130567645197807"
        iyz="2.90267159366494E-07"
        izz="0.000128913789383877" />
    </inertial>
    <visual>
      <origin
        xyz="0 0 0"
        rpy="0 0 0" />
      <geometry>
        <mesh
          filename="package://sia_agv3/meshes/agv_laser_link.dae" />
      </geometry>
      <material
        name="">
        <color
          rgba="1 1 0.501960784313725 1" />
      </material>
    </visual>
    <collision>
      <origin
        xyz="0 0 0"
        rpy="0 0 0" />
      <geometry>
        <mesh
          filename="package://sia_agv3/meshes/agv_laser_link.dae" />
      </geometry>
    </collision>
  </link>
  <joint
    name="laser_joint"
    type="continuous">
    <origin
      xyz="0 0.67006 -0.529"
      rpy="0 0 0" />
    <parent
      link="base_link" />
    <child
      link="laser_Link" />
    <axis
      xyz="0 0 -1" />
    <limit
      lower="-3.14"
      upper="3.14"
      effort="0"
      velocity="0" />
  </joint>
  



</robot>